#VRML_SIM R2025a utf8
# license: Apache License 2.0
# license url: http://www.apache.org/licenses/LICENSE-2.0
# This is a proto file for Webots for the Ec63
# Extracted from: https://github.com/Elite-Robots/ROS/blob/master/src/elite_description/urdf/gazebo/ec63_description.urdf

PROTO Ec63 [
  field  SFVec3f     translation     0 0 0
  field  SFRotation  rotation        0 0 1 0
  field  SFString    name            "Ec63"  # Is `Robot.name`.
  field  SFString    controller      "void"  # Is `Robot.controller`.
  field  MFString    controllerArgs  []      # Is `Robot.controllerArgs`.
  field  SFString    customData      ""      # Is `Robot.customData`.
  field  SFBool      supervisor      FALSE   # Is `Robot.supervisor`.
  field  SFBool      synchronization TRUE    # Is `Robot.synchronization`.
  field  SFBool      selfCollision   FALSE   # Is `Robot.selfCollision`.
]
{
  Robot {
    translation IS translation
    rotation IS rotation
    controller IS controller
    controllerArgs IS controllerArgs
    customData IS customData
    supervisor IS supervisor
    synchronization IS synchronization
    selfCollision IS selfCollision
    children [
      Solid {
        children [
          Shape {
            appearance DEF base_link_material PBRAppearance {
              baseColor 0.792160 0.819610 0.933330
              roughness 1.000000
              metalness 0
            }
            geometry DEF base_link Mesh {
              url "meshes/ec63/base_link.STL"
            }
          }
          HingeJoint {
            jointParameters HingeJointParameters {
              axis 0.000000 0.000000 1.000000
              anchor 0.000000 0.000000 0.140000
            }
            device [
              RotationalMotor {
                name "joint1"
                maxVelocity 3.3161
                minPosition -6.2832
                maxPosition 6.2832
                maxTorque 90.0
              }
              PositionSensor {
                name "joint1_sensor"
              }
            ]
            endPoint Solid {
              translation 0.000000 0.000000 0.140000
              children [
                Shape {
                  appearance DEF link1_material PBRAppearance {
                    roughness 1.000000
                    metalness 0
                  }
                  geometry DEF link1 Mesh {
                    url "meshes/ec63/link1.STL"
                  }
                }
                HingeJoint {
                  jointParameters HingeJointParameters {
                    axis 0.000000 1.000000 -0.000004
                  }
                  device [
                    RotationalMotor {
                      name "joint2"
                      maxVelocity 3.3161
                      minPosition -6.2832
                      maxPosition 6.2832
                      maxTorque 90.0
                    }
                    PositionSensor {
                      name "joint2_sensor"
                    }
                  ]
                  endPoint Solid {
                    rotation -1.000000 0.000000 0.000000 1.570800
                    children [
                      Shape {
                        appearance DEF link2_material PBRAppearance {
                          roughness 1.000000
                          metalness 0
                        }
                        geometry DEF link2 Mesh {
                          url "meshes/ec63/link2.STL"
                        }
                      }
                      HingeJoint {
                        jointParameters HingeJointParameters {
                          axis 0.000000 0.000000 1.000000
                          anchor 0.270000 0.000000 0.000000
                        }
                        device [
                          RotationalMotor {
                            name "joint3"
                            maxVelocity 3.3161
                            minPosition -2.7925
                            maxPosition 2.7925
                            maxTorque 90.0
                          }
                          PositionSensor {
                            name "joint3_sensor"
                          }
                        ]
                        endPoint Solid {
                          translation 0.270000 0.000000 0.000000
                          children [
                            Shape {
                              appearance DEF link3_material PBRAppearance {
                                roughness 1.000000
                                metalness 0
                              }
                              geometry DEF link3 Mesh {
                                url "meshes/ec63/link3.STL"
                              }
                            }
                            HingeJoint {
                              jointParameters HingeJointParameters {
                                axis 0.000000 0.000000 1.000000
                                anchor 0.256000 0.000000 0.000000
                              }
                              device [
                                RotationalMotor {
                                  name "joint4"
                                  maxVelocity 4.5379
                                  minPosition -6.2832
                                  maxPosition 6.2832
                                  maxTorque 20.0
                                }
                                PositionSensor {
                                  name "joint4_sensor"
                                }
                              ]
                              endPoint Solid {
                                translation 0.256000 0.000000 0.000000
                                children [
                                  Shape {
                                    appearance DEF link4_material PBRAppearance {
                                      roughness 1.000000
                                      metalness 0
                                    }
                                    geometry DEF link4 Mesh {
                                      url "meshes/ec63/link4.STL"
                                    }
                                  }
                                  HingeJoint {
                                    jointParameters HingeJointParameters {
                                      axis 0.000000 1.000000 -0.000004
                                      anchor 0.000000 0.000000 0.103000
                                    }
                                    device [
                                      RotationalMotor {
                                        name "joint5"
                                        maxVelocity 4.5379
                                        minPosition -6.2832
                                        maxPosition 6.2832
                                        maxTorque 20.0
                                      }
                                      PositionSensor {
                                        name "joint5_sensor"
                                      }
                                    ]
                                    endPoint Solid {
                                      translation 0.000000 0.000000 0.103000
                                      rotation -1.000000 0.000000 0.000000 1.570800
                                      children [
                                        Shape {
                                          appearance DEF link5_material PBRAppearance {
                                            roughness 1.000000
                                            metalness 0
                                          }
                                          geometry DEF link5 Mesh {
                                            url "meshes/ec63/link5.STL"
                                          }
                                        }
                                        HingeJoint {
                                          jointParameters HingeJointParameters {
                                            axis 0.000000 1.000000 -0.000004
                                            anchor 0.000000 0.089000 0.098000
                                          }
                                          device [
                                            RotationalMotor {
                                              name "joint6"
                                              maxVelocity 4.5379
                                              minPosition -6.2832
                                              maxPosition 6.2832
                                              maxTorque 20.0
                                            }
                                            PositionSensor {
                                              name "joint6_sensor"
                                            }
                                          ]
                                          endPoint Solid {
                                            translation 0.000000 0.089000 0.098000
                                            rotation -1.000000 0.000000 0.000000 1.570800
                                            children [
                                              Shape {
                                                appearance DEF link6_material PBRAppearance {
                                                  baseColor 0.792160 0.819610 0.933330
                                                  roughness 1.000000
                                                  metalness 0
                                                }
                                                geometry DEF link6 Mesh {
                                                  url "meshes/ec63/link6.STL"
                                                }
                                              }
                                            ]
                                            name "link6"
                                            boundingObject USE link6
                                            physics Physics {
                                              density -1
                                              mass 0.164670
                                              centerOfMass [ 0.000000 0.000026 -0.021697 ]
                                              inertiaMatrix [
                                                7.760700e-05 7.780800e-05 1.175300e-04
                                                1.475300e-10 1.060200e-13 -7.848600e-08
                                              ]
                                            }
                                          }
                                        }
                                      ]
                                      name "link5"
                                      boundingObject USE link5
                                      physics Physics {
                                        density -1
                                        mass 0.534360
                                        centerOfMass [ -0.000001 -0.001203 0.091994 ]
                                        inertiaMatrix [
                                          4.148600e-04 4.403000e-04 3.766900e-04
                                          -4.490100e-09 -1.109900e-09 -5.828300e-05
                                        ]
                                      }
                                    }
                                  }
                                ]
                                name "link4"
                                boundingObject USE link4
                                physics Physics {
                                  density -1
                                  mass 0.534360
                                  centerOfMass [ -0.000001 -0.000703 0.097494 ]
                                  inertiaMatrix [
                                    4.148600e-04 4.403000e-04 3.766900e-04
                                    -4.486800e-09 -1.098900e-09 -5.828300e-05
                                  ]
                                }
                              }
                            }
                          ]
                          name "link3"
                          boundingObject USE link3
                          physics Physics {
                            density -1
                            mass 1.449200
                            centerOfMass [ 0.128950 -0.000012 0.011444 ]
                            inertiaMatrix [
                              1.276400e-03 2.052900e-03 2.054200e-03
                              -3.063600e-08 7.348000e-05 -2.150200e-07
                            ]
                          }
                        }
                      }
                    ]
                    name "link2"
                    boundingObject USE link2
                    physics Physics {
                      density -1
                      mass 2.643900
                      centerOfMass [ 0.134990 -0.000001 0.120530 ]
                      inertiaMatrix [
                        3.293900e-03 4.423800e-03 4.596000e-03
                        -2.742900e-08 -3.997000e-09 -1.436700e-07
                      ]
                    }
                  }
                }
              ]
              name "link1"
              boundingObject USE link1
              physics Physics {
                density -1
                mass 1.046899
                centerOfMass [ -0.000001 0.007188 0.001306 ]
                inertiaMatrix [
                  1.316228e-03 1.210417e-03 1.402003e-03
                  1.336260e-08 1.222675e-08 -1.674948e-04
                ]
              }
            }
          }
        ]
        name "base_link"
        boundingObject USE base_link
        physics Physics {
          density -1
          mass 0.364700
          centerOfMass [ 0.000066 0.000017 0.036471 ]
          inertiaMatrix [
            5.905700e-04 5.893400e-04 7.465600e-04
            6.230600e-07 6.602900e-07 -4.802800e-08
          ]
        }
      }
    ]
    name IS name
  }
}
